#VRML_SIM R2023b utf8

EXTERNPROTO "https://raw.githubusercontent.com/cyberbotics/webots/R2023b/projects/objects/backgrounds/protos/TexturedBackground.proto"
EXTERNPROTO "https://raw.githubusercontent.com/cyberbotics/webots/R2023b/projects/objects/backgrounds/protos/TexturedBackgroundLight.proto"
EXTERNPROTO "https://raw.githubusercontent.com/cyberbotics/webots/R2023b/projects/objects/floors/protos/RectangleArena.proto"

WorldInfo {
}
Viewpoint {
  orientation -0.6468980007474439 0.114602701395697 0.7539159087469695 2.876045208744279
  position 0.8535624274530512 -0.3276351881064251 6.070230955648485
}
TexturedBackground {
}
TexturedBackgroundLight {
}
RectangleArena {
  rotation 0 0 -1 0.0458149
  floorSize 2 2
}
Robot {
  children [
    Pose {
      translation -0.0467 0.047 0.0252
      rotation 1 0 0 -3.1415923071795864
      children [
        DEF SCREW Group {
          children [
            Transform {
              scale 1.1 1.1 1.1
              children [
                Shape {
                  appearance PBRAppearance {
                    baseColorMap ImageTexture {
                      url [
                        "https://raw.githubusercontent.com/cyberbotics/webots/R2023b/projects/appearances/protos/textures/old_steel/old_steel_base_color.jpg"
                      ]
                    }
                    roughnessMap ImageTexture {
                      url [
                        "https://raw.githubusercontent.com/cyberbotics/webots/R2023b/projects/appearances/protos/textures/old_steel/old_steel_roughness.jpg"
                      ]
                    }
                    metalnessMap ImageTexture {
                      url [
                        "https://raw.githubusercontent.com/cyberbotics/webots/R2023b/projects/appearances/protos/textures/old_steel/old_steel_metalness.jpg"
                      ]
                    }
                    normalMap ImageTexture {
                      url [
                        "https://raw.githubusercontent.com/cyberbotics/webots/R2023b/projects/appearances/protos/textures/old_steel/old_steel_normal.jpg"
                      ]
                    }
                  }
                  geometry Mesh {
                    url [
                      "https://raw.githubusercontent.com/cyberbotics/webots/R2023b/projects/robots/universal_robots/protos/UR5e/meshes/screw.obj"
                    ]
                  }
                }
              ]
            }
            DEF CYLINDER Pose {
              translation 0 0 0.02
              children [
                Shape {
                  appearance PBRAppearance {
                    baseColorMap ImageTexture {
                      url [
                        "https://raw.githubusercontent.com/cyberbotics/webots/R2023b/projects/appearances/protos/textures/screw_thread/screw_thread_base_color.jpg"
                      ]
                    }
                    roughnessMap ImageTexture {
                      url [
                        "https://raw.githubusercontent.com/cyberbotics/webots/R2023b/projects/appearances/protos/textures/screw_thread/screw_thread_roughness.jpg"
                      ]
                    }
                    normalMap ImageTexture {
                      url [
                        "https://raw.githubusercontent.com/cyberbotics/webots/R2023b/projects/appearances/protos/textures/screw_thread/screw_thread_normal.jpg"
                      ]
                    }
                    occlusionMap ImageTexture {
                      url [
                        "https://raw.githubusercontent.com/cyberbotics/webots/R2023b/projects/appearances/protos/textures/screw_thread/screw_thread_occlusion.jpg"
                      ]
                    }
                    textureTransform TextureTransform {
                      rotation 1.5708
                      scale 1.6 2
                    }
                  }
                  geometry Cylinder {
                    height 0.04
                    radius 0.0044
                  }
                }
              ]
            }
          ]
        }
      ]
    }
    Pose {
      translation -0.0467 -0.047 0.0252
      rotation 1 0 0 -3.1415923071795864
      children [
        USE SCREW
      ]
    }
    Pose {
      translation 0.0464 -0.047 0.0252
      rotation 1 0 0 -3.1415923071795864
      children [
        USE SCREW
      ]
    }
    Pose {
      translation 0.0464 0.047 0.0252
      rotation 1 0 0 -3.1415923071795864
      children [
        USE SCREW
      ]
    }
    Shape {
      appearance DEF METAL_APPEARANCE PBRAppearance {
        baseColor 0.6 0.6 0.6
        roughness 0.7
      }
      geometry Mesh {
        url [
          "https://raw.githubusercontent.com/cyberbotics/webots/R2023b/projects/robots/universal_robots/protos/UR5e/meshes/base_link_0.obj"
        ]
      }
    }
    Shape {
      appearance DEF JOINT_APPEARANCE PBRAppearance {
        baseColor 0 0 0
        roughness 1
        metalness 0
      }
      geometry Mesh {
        url [
          "https://raw.githubusercontent.com/cyberbotics/webots/R2023b/projects/robots/universal_robots/protos/UR5e/meshes/base_link_1.obj"
        ]
      }
    }
    HingeJoint {
      jointParameters HingeJointParameters {
        position -0.5683993337262969
        axis 0 0 1
        anchor 0 0 0.163
      }
      device [
        RotationalMotor {
          name "shoulder_pan_joint"
          maxVelocity 3.14
          minPosition -6.28318530718
          maxPosition 6.28318530718
          maxTorque 150
        }
        PositionSensor {
          name "shoulder_pan_joint_sensor"
        }
      ]
      endPoint Solid {
        translation 0 0 0.163
        rotation 0 0 -1 0.5683993337262971
        children [
          Shape {
            appearance USE METAL_APPEARANCE
            geometry Mesh {
              url [
                "https://raw.githubusercontent.com/cyberbotics/webots/R2023b/projects/robots/universal_robots/protos/UR5e/meshes/shoulder_link_0.obj"
              ]
            }
          }
          Shape {
            appearance USE JOINT_APPEARANCE
            geometry Mesh {
              url [
                "https://raw.githubusercontent.com/cyberbotics/webots/R2023b/projects/robots/universal_robots/protos/UR5e/meshes/shoulder_link_1.obj"
              ]
            }
          }
          Shape {
            appearance PBRAppearance {
              baseColor 0.4902 0.678431 0.8
              roughness 0.4
              metalness 0
              normalMap ImageTexture {
                url [
                  "https://raw.githubusercontent.com/cyberbotics/webots/R2023b/projects/robots/universal_robots/protos/UR5e/textures/normal_0.jpg"
                ]
              }
              occlusionMap ImageTexture {
                url [
                  "https://raw.githubusercontent.com/cyberbotics/webots/R2023b/projects/robots/universal_robots/protos/UR5e/textures/occlusion_0.jpg"
                ]
              }
            }
            geometry Mesh {
              url [
                "https://raw.githubusercontent.com/cyberbotics/webots/R2023b/projects/robots/universal_robots/protos/UR5e/meshes/shoulder_link_2.obj"
              ]
            }
          }
          Shape {
            appearance DEF SCREW_APPEARANCE PBRAppearance {
            }
            geometry Mesh {
              url [
                "https://raw.githubusercontent.com/cyberbotics/webots/R2023b/projects/robots/universal_robots/protos/UR5e/meshes/shoulder_link_3.obj"
              ]
            }
          }
          HingeJoint {
            jointParameters HingeJointParameters {
              position -1.062326666021137
              axis 0 1 0
              anchor 0 0.138 0
            }
            device [
              RotationalMotor {
                name "shoulder_lift_joint"
                maxVelocity 3.14
                minPosition -6.28318530718
                maxPosition 6.28318530718
                maxTorque 150
              }
              PositionSensor {
                name "shoulder_lift_joint_sensor"
              }
            ]
            endPoint Solid {
              translation 0.00013197437582643224 0.13799997191536725 -0.00014009116837033022
              rotation 4.067399770041715e-05 0.9999999972358705 6.224054026428364e-05 0.5084735230317049
              children [
                Shape {
                  appearance PBRAppearance {
                    baseColor 0.4902 0.678431 0.8
                    roughness 0.4
                    metalness 0
                    normalMap ImageTexture {
                      url [
                        "https://raw.githubusercontent.com/cyberbotics/webots/R2023b/projects/robots/universal_robots/protos/UR5e/textures/normal_1.jpg"
                      ]
                    }
                    occlusionMap ImageTexture {
                      url [
                        "https://raw.githubusercontent.com/cyberbotics/webots/R2023b/projects/robots/universal_robots/protos/UR5e/textures/occlusion_1.jpg"
                      ]
                    }
                  }
                  geometry Mesh {
                    url [
                      "https://raw.githubusercontent.com/cyberbotics/webots/R2023b/projects/robots/universal_robots/protos/UR5e/meshes/upper_arm_link_0.obj"
                    ]
                  }
                }
                Shape {
                  appearance USE SCREW_APPEARANCE
                  geometry Mesh {
                    url [
                      "https://raw.githubusercontent.com/cyberbotics/webots/R2023b/projects/robots/universal_robots/protos/UR5e/meshes/upper_arm_link_1.obj"
                    ]
                  }
                }
                Shape {
                  appearance USE METAL_APPEARANCE
                  geometry Mesh {
                    url [
                      "https://raw.githubusercontent.com/cyberbotics/webots/R2023b/projects/robots/universal_robots/protos/UR5e/meshes/upper_arm_link_2.obj"
                    ]
                  }
                }
                Shape {
                  appearance USE JOINT_APPEARANCE
                  geometry Mesh {
                    url [
                      "https://raw.githubusercontent.com/cyberbotics/webots/R2023b/projects/robots/universal_robots/protos/UR5e/meshes/upper_arm_link_3.obj"
                    ]
                  }
                }
                Shape {
                  appearance PBRAppearance {
                    baseColor 0.4902 0.678431 0.8
                    roughness 0.4
                    metalness 0
                    normalMap ImageTexture {
                      url [
                        "https://raw.githubusercontent.com/cyberbotics/webots/R2023b/projects/robots/universal_robots/protos/UR5e/textures/normal_2.jpg"
                      ]
                    }
                    occlusionMap ImageTexture {
                      url [
                        "https://raw.githubusercontent.com/cyberbotics/webots/R2023b/projects/robots/universal_robots/protos/UR5e/textures/occlusion_2.jpg"
                      ]
                    }
                  }
                  geometry Mesh {
                    url [
                      "https://raw.githubusercontent.com/cyberbotics/webots/R2023b/projects/robots/universal_robots/protos/UR5e/meshes/upper_arm_link_4.obj"
                    ]
                  }
                }
                Shape {
                  appearance USE SCREW_APPEARANCE
                  geometry Mesh {
                    url [
                      "https://raw.githubusercontent.com/cyberbotics/webots/R2023b/projects/robots/universal_robots/protos/UR5e/meshes/upper_arm_link_5.obj"
                    ]
                  }
                }
                Shape {
                  appearance DEF METAL_APPEARANCE_LIGHT PBRAppearance {
                    roughness 0.7
                  }
                  geometry Mesh {
                    url [
                      "https://raw.githubusercontent.com/cyberbotics/webots/R2023b/projects/robots/universal_robots/protos/UR5e/meshes/upper_arm_link_6.obj"
                    ]
                  }
                }
                Shape {
                  appearance USE JOINT_APPEARANCE
                  geometry Mesh {
                    url [
                      "https://raw.githubusercontent.com/cyberbotics/webots/R2023b/projects/robots/universal_robots/protos/UR5e/meshes/upper_arm_link_7.obj"
                    ]
                  }
                }
                Shape {
                  appearance USE METAL_APPEARANCE
                  geometry Mesh {
                    url [
                      "https://raw.githubusercontent.com/cyberbotics/webots/R2023b/projects/robots/universal_robots/protos/UR5e/meshes/upper_arm_link_8.obj"
                    ]
                  }
                }
                Shape {
                  appearance USE JOINT_APPEARANCE
                  geometry Mesh {
                    url [
                      "https://raw.githubusercontent.com/cyberbotics/webots/R2023b/projects/robots/universal_robots/protos/UR5e/meshes/upper_arm_link_9.obj"
                    ]
                  }
                }
                HingeJoint {
                  jointParameters HingeJointParameters {
                    position 1.1963985918387556
                    axis 0 1 0
                    anchor 0 -0.131 0.425
                  }
                  device [
                    RotationalMotor {
                      name "elbow_joint"
                      maxVelocity 3.14
                      minPosition -3.14159265359
                      maxPosition 3.14159265359
                      maxTorque 150
                    }
                    PositionSensor {
                      name "elbow_joint_sensor"
                    }
                  ]
                  endPoint Solid {
                    translation 0 -0.131 0.425
                    rotation 0 1 0 1.1963985918387559
                    children [
                      Shape {
                        appearance USE METAL_APPEARANCE
                        geometry Mesh {
                          url [
                            "https://raw.githubusercontent.com/cyberbotics/webots/R2023b/projects/robots/universal_robots/protos/UR5e/meshes/forearm_link_0.obj"
                          ]
                        }
                      }
                      Shape {
                        appearance USE METAL_APPEARANCE
                        geometry Mesh {
                          url [
                            "https://raw.githubusercontent.com/cyberbotics/webots/R2023b/projects/robots/universal_robots/protos/UR5e/meshes/forearm_link_1.obj"
                          ]
                        }
                      }
                      Shape {
                        appearance USE JOINT_APPEARANCE
                        geometry Mesh {
                          url [
                            "https://raw.githubusercontent.com/cyberbotics/webots/R2023b/projects/robots/universal_robots/protos/UR5e/meshes/forearm_link_2.obj"
                          ]
                        }
                      }
                      Shape {
                        appearance USE METAL_APPEARANCE_LIGHT
                        geometry Mesh {
                          url [
                            "https://raw.githubusercontent.com/cyberbotics/webots/R2023b/projects/robots/universal_robots/protos/UR5e/meshes/forearm_link_3.obj"
                          ]
                        }
                      }
                      Shape {
                        appearance USE JOINT_APPEARANCE
                        geometry Mesh {
                          url [
                            "https://raw.githubusercontent.com/cyberbotics/webots/R2023b/projects/robots/universal_robots/protos/UR5e/meshes/forearm_link_4.obj"
                          ]
                        }
                      }
                      Shape {
                        appearance PBRAppearance {
                          baseColor 0.4902 0.678431 0.8
                          roughness 0.4
                          metalness 0
                          normalMap ImageTexture {
                            url [
                              "https://raw.githubusercontent.com/cyberbotics/webots/R2023b/projects/robots/universal_robots/protos/UR5e/textures/normal_3.jpg"
                            ]
                          }
                          occlusionMap ImageTexture {
                            url [
                              "https://raw.githubusercontent.com/cyberbotics/webots/R2023b/projects/robots/universal_robots/protos/UR5e/textures/occlusion_3.jpg"
                            ]
                          }
                        }
                        geometry Mesh {
                          url [
                            "https://raw.githubusercontent.com/cyberbotics/webots/R2023b/projects/robots/universal_robots/protos/UR5e/meshes/forearm_link_5.obj"
                          ]
                        }
                      }
                      Shape {
                        appearance USE SCREW_APPEARANCE
                        geometry Mesh {
                          url [
                            "https://raw.githubusercontent.com/cyberbotics/webots/R2023b/projects/robots/universal_robots/protos/UR5e/meshes/forearm_link_6.obj"
                          ]
                        }
                      }
                      Shape {
                        appearance USE JOINT_APPEARANCE
                        geometry Mesh {
                          url [
                            "https://raw.githubusercontent.com/cyberbotics/webots/R2023b/projects/robots/universal_robots/protos/UR5e/meshes/forearm_link_7.obj"
                          ]
                        }
                      }
                      HingeJoint {
                        jointParameters HingeJointParameters {
                          position -0.0005196325424721002
                          axis 0 1 0
                          anchor 0 0 0.392
                        }
                        device [
                          RotationalMotor {
                            name "wrist_1_joint"
                            maxVelocity 6.28
                            minPosition -6.283201047036033
                            maxPosition 6.28318530718
                            maxTorque 28
                          }
                          PositionSensor {
                            name "wrist_1_joint_sensor"
                          }
                        ]
                        endPoint DEF GPS_TP Solid {
                          translation 0 0 0.392
                          rotation 0 1 0 1.5702763674575193
                          children [
                            Shape {
                              appearance USE METAL_APPEARANCE
                              geometry Mesh {
                                url [
                                  "https://raw.githubusercontent.com/cyberbotics/webots/R2023b/projects/robots/universal_robots/protos/UR5e/meshes/wrist_1_link_0.obj"
                                ]
                              }
                            }
                            Shape {
                              appearance PBRAppearance {
                                baseColor 0.4902 0.678431 0.8
                                roughness 0.4
                                metalness 0
                                normalMap ImageTexture {
                                  url [
                                    "https://raw.githubusercontent.com/cyberbotics/webots/R2023b/projects/robots/universal_robots/protos/UR5e/textures/normal_4.jpg"
                                  ]
                                }
                                occlusionMap ImageTexture {
                                  url [
                                    "https://raw.githubusercontent.com/cyberbotics/webots/R2023b/projects/robots/universal_robots/protos/UR5e/textures/occlusion_4.jpg"
                                  ]
                                }
                              }
                              geometry Mesh {
                                url [
                                  "https://raw.githubusercontent.com/cyberbotics/webots/R2023b/projects/robots/universal_robots/protos/UR5e/meshes/wrist_1_link_1.obj"
                                ]
                              }
                            }
                            Shape {
                              appearance USE SCREW_APPEARANCE
                              geometry Mesh {
                                url [
                                  "https://raw.githubusercontent.com/cyberbotics/webots/R2023b/projects/robots/universal_robots/protos/UR5e/meshes/wrist_1_link_2.obj"
                                ]
                              }
                            }
                            Shape {
                              appearance USE JOINT_APPEARANCE
                              geometry Mesh {
                                url [
                                  "https://raw.githubusercontent.com/cyberbotics/webots/R2023b/projects/robots/universal_robots/protos/UR5e/meshes/wrist_1_link_3.obj"
                                ]
                              }
                            }
                          ]
                          name "wrist_1_link"
                          boundingObject Group {
                            children [
                              Pose {
                                translation 0 0.089 0
                                rotation 1 0 0 -1.57079632679
                                children [
                                  Cylinder {
                                    height 0.086
                                    radius 0.038
                                  }
                                ]
                              }
                              Pose {
                                translation 0 0.126 0
                                children [
                                  Cylinder {
                                    height 0.112
                                    radius 0.038
                                  }
                                ]
                              }
                            ]
                          }
                          physics Physics {
                            density -1
                            mass 1.37
                            centerOfMass [
                              0 0.127 0
                            ]
                          }
                          linearVelocity 0.6955049842982416 1.8279099781990988 -0.0422485405361807
                          angularVelocity 0.10118820609327465 0.17083122844481086 3.1455910681753316
                        }
                      }
                    ]
                    name "forearm_link"
                    boundingObject Group {
                      children [
                        Pose {
                          translation 0 0 0.207
                          children [
                            Cylinder {
                              height 0.36
                              radius 0.038
                            }
                          ]
                        }
                        Pose {
                          translation 0 -0.001 0.39
                          rotation 1 0 0 -1.57079632679
                          children [
                            Cylinder {
                              height 0.109
                              radius 0.039
                            }
                          ]
                        }
                        Pose {
                          translation 0 0.06 0
                          rotation 1 0 0 1.57079632679
                          children [
                            Capsule {
                              height 0.05
                              radius 0.058
                              subdivision 16
                            }
                          ]
                        }
                        Pose {
                          translation 0 0 0.07
                          children [
                            Capsule {
                              height 0.1
                              radius 0.04
                              subdivision 16
                            }
                          ]
                        }
                      ]
                    }
                    physics Physics {
                      density -1
                      mass 2.846
                      centerOfMass [
                        0 0 0.15
                      ]
                    }
                    linearVelocity 0.575771090612182 0.9694678504571053 0.0048606623176609765
                    angularVelocity 0.10120733644576024 0.17085452035002763 3.145593224323632
                  }
                }
              ]
              name "upper_arm_link"
              boundingObject Group {
                children [
                  Pose {
                    translation 0 0 0.22
                    children [
                      Cylinder {
                        height 0.407
                        radius 0.059
                      }
                    ]
                  }
                  Pose {
                    rotation 1 0 0 -1.57079632679
                    children [
                      Cylinder {
                        height 0.133
                        radius 0.059
                      }
                    ]
                  }
                  Pose {
                    translation 0 -0.005 0.424
                    rotation 1 0 0 -1.57079632679
                    children [
                      Cylinder {
                        height 0.149
                        radius 0.059
                      }
                    ]
                  }
                ]
              }
              physics Physics {
                density -1
                mass 8.058
                centerOfMass [
                  0 0 0.2125
                ]
              }
              linearVelocity -0.19393411136313418 0.5453147556163495 0.01700375411009876
              angularVelocity -0.09039477025850336 -0.16249082029741097 3.1429920517778664
            }
          }
        ]
        name "shoulder_link"
        boundingObject Group {
          children [
            Pose {
              children [
                Cylinder {
                  height 0.135
                  radius 0.059
                }
              ]
            }
            Pose {
              translation 0 0.03 0
              rotation 1 0 0 -1.57079632679
              children [
                Cylinder {
                  height 0.093
                  radius 0.059
                }
              ]
            }
          ]
        }
        physics Physics {
          density -1
          mass 3.761
          centerOfMass [
            0 -0.02561 0.00193
          ]
        }
        linearVelocity 0.06570816755750217 -0.047873877189480954 -2.5553816472698245e-05
        angularVelocity -2.7008951344581457e-05 4.443082002411361e-06 3.140020361747028
      }
    }
  ]
  name "UR5e"
  model "UR5e"
  boundingObject Pose {
    translation 0 0 0.05
    children [
      Cylinder {
        height 0.1
        radius 0.076
      }
    ]
  }
  controller "random_dataset_generator"
  supervisor TRUE
  selfCollision TRUE
}
DEF TARGET_BALL Solid {
  translation 0.35042 -0.615759 0.5
  children [
    Shape {
      appearance Appearance {
        material Material {
          diffuseColor 1 0 0
        }
      }
      geometry Sphere {
        radius 0.04
      }
    }
  ]
}
